<?xml version='1.0' encoding='utf-8'?>
<mujoco><compiler angle="radian" autolimits="true" /><option integrator="implicitfast" cone="elliptic" impratio="100" /><default><default class="iiwa">
      <material specular="0.5" shininess="0.25" />
      <joint axis="0 0 1" />
      <general gaintype="fixed" biastype="affine" gainprm="2000" biasprm="0 -2000 -200" />
      <default class="joint1_iiwa">
        <joint range="-2.96706 2.96706" />
        <general ctrlrange="-2.96706 2.96706" />
        <default class="joint2_iiwa">
          <joint range="-2.0944 2.0944" />
          <general ctrlrange="-2.0944 2.0944" />
        </default>
      </default>
      <default class="joint3_iiwa">
        <joint range="-3.05433 3.05433" />
        <general ctrlrange="-3.05433 3.05433" />
      </default>
      <default class="visual_iiwa">
        <geom type="mesh" contype="0" conaffinity="0" group="2" material="gray_iiwa" />
      </default>
      <default class="collision_iiwa">
        <geom group="3" />
      </default>
      <site size="0.001" rgba="1 0 0 1" group="4" />
    </default>
  <default class="fr3">
      <joint armature="0.1" damping="1" />
      <position inheritrange="1" />
      <default class="visual_fr3">
        <geom type="mesh" group="2" contype="0" conaffinity="0" />
      </default>
      <default class="collision_fr3">
        <geom type="mesh" group="3" mass="0" density="0" />
      </default>
      <site size="0.001" rgba="0.5 0.5 0.5 0.3" group="4" />
    </default>
  <default class="panda">
      <material specular="0.5" shininess="0.25" />
      <joint armature="0.1" damping="1" axis="0 0 1" range="-2.8973 2.8973" />
      <general dyntype="none" biastype="affine" ctrlrange="-2.8973 2.8973" forcerange="-87 87" />
      <default class="finger_panda">
        <joint axis="0 1 0" type="slide" range="0 0.04" />
      </default>

      <default class="visual_panda">
        <geom type="mesh" contype="0" conaffinity="0" group="2" />
      </default>
      <default class="collision_panda">
        <geom type="mesh" group="3" />
        <default class="fingertip_pad_collision_1_panda">
          <geom type="box" size="0.0085 0.004 0.0085" pos="0 0.0055 0.0445" />
        </default>
        <default class="fingertip_pad_collision_2_panda">
          <geom type="box" size="0.003 0.002 0.003" pos="0.0055 0.002 0.05" />
        </default>
        <default class="fingertip_pad_collision_3_panda">
          <geom type="box" size="0.003 0.002 0.003" pos="-0.0055 0.002 0.05" />
        </default>
        <default class="fingertip_pad_collision_4_panda">
          <geom type="box" size="0.003 0.002 0.0035" pos="0.0055 0.002 0.0395" />
        </default>
        <default class="fingertip_pad_collision_5_panda">
          <geom type="box" size="0.003 0.002 0.0035" pos="-0.0055 0.002 0.0395" />
        </default>
      </default>
    </default>
  </default><asset><material class="iiwa" name="gray_iiwa" rgba="0.4 0.4 0.4 1" />
    <material class="iiwa" name="light_gray_iiwa" rgba="0.6 0.6 0.6 1" />
    <material class="iiwa" name="black_iiwa" rgba="0 0 0 1" />
    <material class="iiwa" name="orange_iiwa" rgba="1 0.423529 0.0392157 1" />

    <mesh file="assets_iiwa/link_0.obj" name="link_0_iiwa" />
    <mesh file="assets_iiwa/link_1.obj" name="link_1_iiwa" />
    <mesh file="assets_iiwa/link_2_orange.obj" name="link_2_orange_iiwa" />
    <mesh file="assets_iiwa/link_2_grey.obj" name="link_2_grey_iiwa" />
    <mesh file="assets_iiwa/link_3.obj" name="link_3_iiwa" />
    <mesh file="assets_iiwa/band.obj" name="band_iiwa" />
    <mesh file="assets_iiwa/kuka.obj" name="kuka_iiwa" />
    <mesh file="assets_iiwa/link_4_orange.obj" name="link_4_orange_iiwa" />
    <mesh file="assets_iiwa/link_4_grey.obj" name="link_4_grey_iiwa" />
    <mesh file="assets_iiwa/link_5.obj" name="link_5_iiwa" />
    <mesh file="assets_iiwa/link_6_orange.obj" name="link_6_orange_iiwa" />
    <mesh file="assets_iiwa/link_6_grey.obj" name="link_6_grey_iiwa" />
    <mesh file="assets_iiwa/link_7.obj" name="link_7_iiwa" />
  <material name="black_fr3" rgba=".2 .2 .2 1" />
    <material name="white_fr3" rgba="1 1 1 1" />
    <material name="red_fr3" rgba="1 0.072272 0.039546 1" />
    <material name="gray_fr3" rgba="0.863156 0.863156 0.863157 1" />
    <material name="button_green_fr3" rgba="0.102241 0.571125 0.102242 1" />
    <material name="button_red_fr3" rgba="0.520996 0.008023 0.013702 1" />
    <material name="button_blue_fr3" rgba="0.024157 0.445201 0.737911 1" />

    <mesh file="assets_fr3/link0_0.obj" name="link0_0_fr3" />
    <mesh file="assets_fr3/link0_1.obj" name="link0_1_fr3" />
    <mesh file="assets_fr3/link0_2.obj" name="link0_2_fr3" />
    <mesh file="assets_fr3/link0_3.obj" name="link0_3_fr3" />
    <mesh file="assets_fr3/link0_4.obj" name="link0_4_fr3" />
    <mesh file="assets_fr3/link0_5.obj" name="link0_5_fr3" />
    <mesh file="assets_fr3/link0_6.obj" name="link0_6_fr3" />
    <mesh file="assets_fr3/link1.obj" name="link1_fr3" />
    <mesh file="assets_fr3/link2.obj" name="link2_fr3" />
    <mesh file="assets_fr3/link3_0.obj" name="link3_0_fr3" />
    <mesh file="assets_fr3/link3_1.obj" name="link3_1_fr3" />
    <mesh file="assets_fr3/link4_0.obj" name="link4_0_fr3" />
    <mesh file="assets_fr3/link4_1.obj" name="link4_1_fr3" />
    <mesh file="assets_fr3/link5_0.obj" name="link5_0_fr3" />
    <mesh file="assets_fr3/link5_1.obj" name="link5_1_fr3" />
    <mesh file="assets_fr3/link5_2.obj" name="link5_2_fr3" />
    <mesh file="assets_fr3/link6_0.obj" name="link6_0_fr3" />
    <mesh file="assets_fr3/link6_1.obj" name="link6_1_fr3" />
    <mesh file="assets_fr3/link6_2.obj" name="link6_2_fr3" />
    <mesh file="assets_fr3/link6_3.obj" name="link6_3_fr3" />
    <mesh file="assets_fr3/link6_4.obj" name="link6_4_fr3" />
    <mesh file="assets_fr3/link6_5.obj" name="link6_5_fr3" />
    <mesh file="assets_fr3/link6_6.obj" name="link6_6_fr3" />
    <mesh file="assets_fr3/link6_7.obj" name="link6_7_fr3" />
    <mesh file="assets_fr3/link7_0.obj" name="link7_0_fr3" />
    <mesh file="assets_fr3/link7_1.obj" name="link7_1_fr3" />
    <mesh file="assets_fr3/link7_2.obj" name="link7_2_fr3" />
    <mesh file="assets_fr3/link7_3.obj" name="link7_3_fr3" />

    <mesh name="link0_coll_fr3" file="assets_fr3/link0.stl" />
    <mesh name="link1_coll_fr3" file="assets_fr3/link1.stl" />
    <mesh name="link2_coll_fr3" file="assets_fr3/link2.stl" />
    <mesh name="link3_coll_fr3" file="assets_fr3/link3.stl" />
    <mesh name="link4_coll_fr3" file="assets_fr3/link4.stl" />
    <mesh name="link5_coll_fr3" file="assets_fr3/link5.stl" />
    <mesh name="link6_coll_fr3" file="assets_fr3/link6.stl" />
    <mesh name="link7_coll_fr3" file="assets_fr3/link7.stl" />
  <material class="panda" name="white_panda" rgba="1 1 1 1" />
    <material class="panda" name="off_white_panda" rgba="0.901961 0.921569 0.929412 1" />
    <material class="panda" name="black_panda" rgba="0.25 0.25 0.25 1" />
    <material class="panda" name="green_panda" rgba="0 1 0 1" />
    <material class="panda" name="light_blue_panda" rgba="0.039216 0.541176 0.780392 1" />

    
    <mesh name="link0_c_panda" file="assets_panda/link0.stl" />
    <mesh name="link1_c_panda" file="assets_panda/link1.stl" />
    <mesh name="link2_c_panda" file="assets_panda/link2.stl" />
    <mesh name="link3_c_panda" file="assets_panda/link3.stl" />
    <mesh name="link4_c_panda" file="assets_panda/link4.stl" />
    <mesh name="link5_c0_panda" file="assets_panda/link5_collision_0.obj" />
    <mesh name="link5_c1_panda" file="assets_panda/link5_collision_1.obj" />
    <mesh name="link5_c2_panda" file="assets_panda/link5_collision_2.obj" />
    <mesh name="link6_c_panda" file="assets_panda/link6.stl" />
    <mesh name="link7_c_panda" file="assets_panda/link7.stl" />
    <mesh name="hand_c_panda" file="assets_panda/hand.stl" />

    
    <mesh file="assets_panda/link0_0.obj" name="link0_0_panda" />
    <mesh file="assets_panda/link0_1.obj" name="link0_1_panda" />
    <mesh file="assets_panda/link0_2.obj" name="link0_2_panda" />
    <mesh file="assets_panda/link0_3.obj" name="link0_3_panda" />
    <mesh file="assets_panda/link0_4.obj" name="link0_4_panda" />
    <mesh file="assets_panda/link0_5.obj" name="link0_5_panda" />
    <mesh file="assets_panda/link0_7.obj" name="link0_7_panda" />
    <mesh file="assets_panda/link0_8.obj" name="link0_8_panda" />
    <mesh file="assets_panda/link0_9.obj" name="link0_9_panda" />
    <mesh file="assets_panda/link0_10.obj" name="link0_10_panda" />
    <mesh file="assets_panda/link0_11.obj" name="link0_11_panda" />
    <mesh file="assets_panda/link1.obj" name="link1_panda" />
    <mesh file="assets_panda/link2.obj" name="link2_panda" />
    <mesh file="assets_panda/link3_0.obj" name="link3_0_panda" />
    <mesh file="assets_panda/link3_1.obj" name="link3_1_panda" />
    <mesh file="assets_panda/link3_2.obj" name="link3_2_panda" />
    <mesh file="assets_panda/link3_3.obj" name="link3_3_panda" />
    <mesh file="assets_panda/link4_0.obj" name="link4_0_panda" />
    <mesh file="assets_panda/link4_1.obj" name="link4_1_panda" />
    <mesh file="assets_panda/link4_2.obj" name="link4_2_panda" />
    <mesh file="assets_panda/link4_3.obj" name="link4_3_panda" />
    <mesh file="assets_panda/link5_0.obj" name="link5_0_panda" />
    <mesh file="assets_panda/link5_1.obj" name="link5_1_panda" />
    <mesh file="assets_panda/link5_2.obj" name="link5_2_panda" />
    <mesh file="assets_panda/link6_0.obj" name="link6_0_panda" />
    <mesh file="assets_panda/link6_1.obj" name="link6_1_panda" />
    <mesh file="assets_panda/link6_2.obj" name="link6_2_panda" />
    <mesh file="assets_panda/link6_3.obj" name="link6_3_panda" />
    <mesh file="assets_panda/link6_4.obj" name="link6_4_panda" />
    <mesh file="assets_panda/link6_5.obj" name="link6_5_panda" />
    <mesh file="assets_panda/link6_6.obj" name="link6_6_panda" />
    <mesh file="assets_panda/link6_7.obj" name="link6_7_panda" />
    <mesh file="assets_panda/link6_8.obj" name="link6_8_panda" />
    <mesh file="assets_panda/link6_9.obj" name="link6_9_panda" />
    <mesh file="assets_panda/link6_10.obj" name="link6_10_panda" />
    <mesh file="assets_panda/link6_11.obj" name="link6_11_panda" />
    <mesh file="assets_panda/link6_12.obj" name="link6_12_panda" />
    <mesh file="assets_panda/link6_13.obj" name="link6_13_panda" />
    <mesh file="assets_panda/link6_14.obj" name="link6_14_panda" />
    <mesh file="assets_panda/link6_15.obj" name="link6_15_panda" />
    <mesh file="assets_panda/link6_16.obj" name="link6_16_panda" />
    <mesh file="assets_panda/link7_0.obj" name="link7_0_panda" />
    <mesh file="assets_panda/link7_1.obj" name="link7_1_panda" />
    <mesh file="assets_panda/link7_2.obj" name="link7_2_panda" />
    <mesh file="assets_panda/link7_3.obj" name="link7_3_panda" />
    <mesh file="assets_panda/link7_4.obj" name="link7_4_panda" />
    <mesh file="assets_panda/link7_5.obj" name="link7_5_panda" />
    <mesh file="assets_panda/link7_6.obj" name="link7_6_panda" />
    <mesh file="assets_panda/link7_7.obj" name="link7_7_panda" />
    <mesh file="assets_panda/hand_0.obj" name="hand_0_panda" />
    <mesh file="assets_panda/hand_1.obj" name="hand_1_panda" />
    <mesh file="assets_panda/hand_2.obj" name="hand_2_panda" />
    <mesh file="assets_panda/hand_3.obj" name="hand_3_panda" />
    <mesh file="assets_panda/hand_4.obj" name="hand_4_panda" />
    <mesh file="assets_panda/finger_0.obj" name="finger_0_panda" />
    <mesh file="assets_panda/finger_1.obj" name="finger_1_panda" />
  </asset><worldbody><body name="base_iiwa_3" childclass="iiwa" pos="2 2 0.0">
      <inertial mass="5" pos="-0.1 0 0.07" diaginertia="0.05 0.06 0.03" />
      <geom class="visual_iiwa" mesh="link_0_iiwa" />
      <geom class="collision_iiwa" size="0.12" pos="0 0 0.03" />
      <geom class="collision_iiwa" size="0.08" pos="-0.08 0 0.103" />
      <geom class="collision_iiwa" size="0.08" pos="-0.08 0 0.04" />
      <geom class="collision_iiwa" size="0.1" pos="0 0 0.14" />
      <body name="link1_iiwa_3" pos="0 0 0.1575">
        <inertial mass="5.76" pos="0 -0.03 0.12" diaginertia="0.0333 0.033 0.0123" />
        <joint name="joint1_iiwa_3" class="joint1_iiwa" />
        <geom class="visual_iiwa" mesh="link_1_iiwa" />
        <geom class="collision_iiwa" size="0.08" pos="0 0 -0.0005" />
        <geom class="collision_iiwa" size="0.075" pos="0.01 -0.025 0.0425" />
        <geom class="collision_iiwa" size="0.075" pos="-0.01 -0.025 0.0425" />
        <geom class="collision_iiwa" size="0.07" pos="0.01 -0.045 0.1025" />
        <geom class="collision_iiwa" size="0.07" pos="-0.01 -0.045 0.1025" />
        <body name="link2_iiwa_3" pos="0 0 0.2025" quat="0 0 1 1">
          <inertial mass="6.35" pos="0.0003 0.059 0.042" diaginertia="0.0305 0.0304 0.011" quat="0 0 1 1" />
          <joint name="joint2_iiwa_3" class="joint2_iiwa" />
          <geom class="visual_iiwa" material="orange_iiwa" mesh="link_2_orange_iiwa" />
          <geom class="visual_iiwa" mesh="link_2_grey_iiwa" />
          <geom class="collision_iiwa" size="0.095" pos="0 0 -0.01" />
          <geom class="collision_iiwa" size="0.09" pos="0 0 0.045" />
          <geom class="collision_iiwa" size="0.07" pos="-0.01 0.04 0.054" />
          <geom class="collision_iiwa" size="0.065" pos="-0.01 0.09 0.04" />
          <geom class="collision_iiwa" size="0.065" pos="-0.01 0.13 0.02" />
          <geom class="collision_iiwa" size="0.07" pos="0.01 0.04 0.054" />
          <geom class="collision_iiwa" size="0.065" pos="0.01 0.09 0.04" />
          <geom class="collision_iiwa" size="0.065" pos="0.01 0.13 0.02" />
          <geom class="collision_iiwa" size="0.075" pos="0 0.18 0" />
          <body name="link3_iiwa_3" pos="0 0.2045 0" quat="0 0 1 1">
            <inertial mass="3.5" pos="0 0.03 0.13" diaginertia="0.025 0.0238 0.0076" />
            <joint name="joint3_iiwa_3" class="joint1_iiwa" />
            <geom class="visual_iiwa" mesh="link_3_iiwa" />
            <geom class="visual_iiwa" material="light_gray_iiwa" mesh="band_iiwa" />
            <geom class="visual_iiwa" material="black_iiwa" mesh="kuka_iiwa" />
            <geom class="collision_iiwa" size="0.075" pos="0 0 0.0355" />
            <geom class="collision_iiwa" size="0.06" pos="0.01 0.023 0.0855" />
            <geom class="collision_iiwa" size="0.055" pos="0.01 0.048 0.1255" />
            <geom class="collision_iiwa" size="0.06" pos="0.01 0.056 0.1755" />
            <geom class="collision_iiwa" size="0.06" pos="-0.01 0.023 0.0855" />
            <geom class="collision_iiwa" size="0.055" pos="-0.01 0.048 0.1255" />
            <geom class="collision_iiwa" size="0.06" pos="-0.01 0.056 0.1755" />
            <geom class="collision_iiwa" size="0.075" pos="0 0.045 0.2155" />
            <geom class="collision_iiwa" size="0.075" pos="0 0 0.2155" />
            <body name="link4_iiwa_3" pos="0 0 0.2155" quat="1 1 0 0">
              <inertial mass="3.5" pos="0 0.067 0.034" diaginertia="0.017 0.0164 0.006" quat="1 1 0 0" />
              <joint name="joint4_iiwa_3" class="joint2_iiwa" />
              <geom class="visual_iiwa" material="orange_iiwa" mesh="link_4_orange_iiwa" />
              <geom class="visual_iiwa" mesh="link_4_grey_iiwa" />
              <geom class="collision_iiwa" size="0.078" pos="0 0.01 0.046" />
              <geom class="collision_iiwa" size="0.06" pos="0.01 0.06 0.052" />
              <geom class="collision_iiwa" size="0.065" pos="0.01 0.12 0.034" />
              <geom class="collision_iiwa" size="0.06" pos="-0.01 0.06 0.052" />
              <geom class="collision_iiwa" size="0.065" pos="-0.01 0.12 0.034" />
              <geom class="collision_iiwa" size="0.075" pos="0 0.184 0" />
              <body name="link5_iiwa_3" pos="0 0.1845 0" quat="0 0 1 1">
                <inertial mass="3.5" pos="0.0001 0.021 0.076" diaginertia="0.01 0.0087 0.00449" />
                <joint name="joint5_iiwa_3" class="joint1_iiwa" />
                <geom class="visual_iiwa" mesh="link_5_iiwa" />
                <geom class="visual_iiwa" material="light_gray_iiwa" mesh="band_iiwa" />
                <geom class="visual_iiwa" material="black_iiwa" mesh="kuka_iiwa" />
                <geom class="collision_iiwa" size="0.075" pos="0 0 0.0335" />
                <geom class="collision_iiwa" size="0.05" pos="-0.012 0.031 0.0755" />
                <geom class="collision_iiwa" size="0.05" pos="0.012 0.031 0.0755" />
                <geom class="collision_iiwa" size="0.04" pos="-0.012 0.06 0.1155" />
                <geom class="collision_iiwa" size="0.04" pos="0.012 0.06 0.1155" />
                <geom class="collision_iiwa" size="0.04" pos="-0.01 0.065 0.1655" />
                <geom class="collision_iiwa" size="0.04" pos="0.01 0.065 0.1655" />
                <geom class="collision_iiwa" size="0.035" pos="-0.012 0.065 0.1855" />
                <geom class="collision_iiwa" size="0.035" pos="0.012 0.065 0.1855" />
                <body name="link6_iiwa_3" pos="0 0 0.2155" quat="1 1 0 0">
                  <inertial mass="1.8" pos="0 0.0006 0.0004" diaginertia="0.0049 0.0047 0.0036" quat="1 1 0 0" />
                  <joint name="joint6_iiwa_3" class="joint2_iiwa" />
                  <geom class="visual_iiwa" material="orange_iiwa" mesh="link_6_orange_iiwa" />
                  <geom class="visual_iiwa" mesh="link_6_grey_iiwa" />
                  <geom class="collision_iiwa" size="0.055" pos="0 0 -0.059" />
                  <geom class="collision_iiwa" size="0.065" pos="0 -0.03 0.011" />
                  <geom class="collision_iiwa" size="0.08" />
                  <body name="link7_iiwa_3" pos="0 0.081 0" quat="0 0 1 1">
                    <inertial mass="1.2" pos="0 0 0.02" diaginertia="0.001 0.001 0.001" />
                    <joint name="joint7_iiwa_3" class="joint3_iiwa" />
                    <geom class="visual_iiwa" mesh="link_7_iiwa" />
                    <geom class="collision_iiwa" size="0.06" pos="0 0 0.001" />
                    <site pos="0 0 0.045" name="attachment_site_iiwa_3" />
                  </body>
                </body>
              </body>
            </body>
          </body>
        </body>
      </body>
    </body>
  <body name="base_iiwa_4" childclass="iiwa" pos="-2.0 -2.0 0.0">
      <inertial mass="5" pos="-0.1 0 0.07" diaginertia="0.05 0.06 0.03" />
      <geom class="visual_iiwa" mesh="link_0_iiwa" />
      <geom class="collision_iiwa" size="0.12" pos="0 0 0.03" />
      <geom class="collision_iiwa" size="0.08" pos="-0.08 0 0.103" />
      <geom class="collision_iiwa" size="0.08" pos="-0.08 0 0.04" />
      <geom class="collision_iiwa" size="0.1" pos="0 0 0.14" />
      <body name="link1_iiwa_4" pos="0 0 0.1575">
        <inertial mass="5.76" pos="0 -0.03 0.12" diaginertia="0.0333 0.033 0.0123" />
        <joint name="joint1_iiwa_4" class="joint1_iiwa" />
        <geom class="visual_iiwa" mesh="link_1_iiwa" />
        <geom class="collision_iiwa" size="0.08" pos="0 0 -0.0005" />
        <geom class="collision_iiwa" size="0.075" pos="0.01 -0.025 0.0425" />
        <geom class="collision_iiwa" size="0.075" pos="-0.01 -0.025 0.0425" />
        <geom class="collision_iiwa" size="0.07" pos="0.01 -0.045 0.1025" />
        <geom class="collision_iiwa" size="0.07" pos="-0.01 -0.045 0.1025" />
        <body name="link2_iiwa_4" pos="0 0 0.2025" quat="0 0 1 1">
          <inertial mass="6.35" pos="0.0003 0.059 0.042" diaginertia="0.0305 0.0304 0.011" quat="0 0 1 1" />
          <joint name="joint2_iiwa_4" class="joint2_iiwa" />
          <geom class="visual_iiwa" material="orange_iiwa" mesh="link_2_orange_iiwa" />
          <geom class="visual_iiwa" mesh="link_2_grey_iiwa" />
          <geom class="collision_iiwa" size="0.095" pos="0 0 -0.01" />
          <geom class="collision_iiwa" size="0.09" pos="0 0 0.045" />
          <geom class="collision_iiwa" size="0.07" pos="-0.01 0.04 0.054" />
          <geom class="collision_iiwa" size="0.065" pos="-0.01 0.09 0.04" />
          <geom class="collision_iiwa" size="0.065" pos="-0.01 0.13 0.02" />
          <geom class="collision_iiwa" size="0.07" pos="0.01 0.04 0.054" />
          <geom class="collision_iiwa" size="0.065" pos="0.01 0.09 0.04" />
          <geom class="collision_iiwa" size="0.065" pos="0.01 0.13 0.02" />
          <geom class="collision_iiwa" size="0.075" pos="0 0.18 0" />
          <body name="link3_iiwa_4" pos="0 0.2045 0" quat="0 0 1 1">
            <inertial mass="3.5" pos="0 0.03 0.13" diaginertia="0.025 0.0238 0.0076" />
            <joint name="joint3_iiwa_4" class="joint1_iiwa" />
            <geom class="visual_iiwa" mesh="link_3_iiwa" />
            <geom class="visual_iiwa" material="light_gray_iiwa" mesh="band_iiwa" />
            <geom class="visual_iiwa" material="black_iiwa" mesh="kuka_iiwa" />
            <geom class="collision_iiwa" size="0.075" pos="0 0 0.0355" />
            <geom class="collision_iiwa" size="0.06" pos="0.01 0.023 0.0855" />
            <geom class="collision_iiwa" size="0.055" pos="0.01 0.048 0.1255" />
            <geom class="collision_iiwa" size="0.06" pos="0.01 0.056 0.1755" />
            <geom class="collision_iiwa" size="0.06" pos="-0.01 0.023 0.0855" />
            <geom class="collision_iiwa" size="0.055" pos="-0.01 0.048 0.1255" />
            <geom class="collision_iiwa" size="0.06" pos="-0.01 0.056 0.1755" />
            <geom class="collision_iiwa" size="0.075" pos="0 0.045 0.2155" />
            <geom class="collision_iiwa" size="0.075" pos="0 0 0.2155" />
            <body name="link4_iiwa_4" pos="0 0 0.2155" quat="1 1 0 0">
              <inertial mass="3.5" pos="0 0.067 0.034" diaginertia="0.017 0.0164 0.006" quat="1 1 0 0" />
              <joint name="joint4_iiwa_4" class="joint2_iiwa" />
              <geom class="visual_iiwa" material="orange_iiwa" mesh="link_4_orange_iiwa" />
              <geom class="visual_iiwa" mesh="link_4_grey_iiwa" />
              <geom class="collision_iiwa" size="0.078" pos="0 0.01 0.046" />
              <geom class="collision_iiwa" size="0.06" pos="0.01 0.06 0.052" />
              <geom class="collision_iiwa" size="0.065" pos="0.01 0.12 0.034" />
              <geom class="collision_iiwa" size="0.06" pos="-0.01 0.06 0.052" />
              <geom class="collision_iiwa" size="0.065" pos="-0.01 0.12 0.034" />
              <geom class="collision_iiwa" size="0.075" pos="0 0.184 0" />
              <body name="link5_iiwa_4" pos="0 0.1845 0" quat="0 0 1 1">
                <inertial mass="3.5" pos="0.0001 0.021 0.076" diaginertia="0.01 0.0087 0.00449" />
                <joint name="joint5_iiwa_4" class="joint1_iiwa" />
                <geom class="visual_iiwa" mesh="link_5_iiwa" />
                <geom class="visual_iiwa" material="light_gray_iiwa" mesh="band_iiwa" />
                <geom class="visual_iiwa" material="black_iiwa" mesh="kuka_iiwa" />
                <geom class="collision_iiwa" size="0.075" pos="0 0 0.0335" />
                <geom class="collision_iiwa" size="0.05" pos="-0.012 0.031 0.0755" />
                <geom class="collision_iiwa" size="0.05" pos="0.012 0.031 0.0755" />
                <geom class="collision_iiwa" size="0.04" pos="-0.012 0.06 0.1155" />
                <geom class="collision_iiwa" size="0.04" pos="0.012 0.06 0.1155" />
                <geom class="collision_iiwa" size="0.04" pos="-0.01 0.065 0.1655" />
                <geom class="collision_iiwa" size="0.04" pos="0.01 0.065 0.1655" />
                <geom class="collision_iiwa" size="0.035" pos="-0.012 0.065 0.1855" />
                <geom class="collision_iiwa" size="0.035" pos="0.012 0.065 0.1855" />
                <body name="link6_iiwa_4" pos="0 0 0.2155" quat="1 1 0 0">
                  <inertial mass="1.8" pos="0 0.0006 0.0004" diaginertia="0.0049 0.0047 0.0036" quat="1 1 0 0" />
                  <joint name="joint6_iiwa_4" class="joint2_iiwa" />
                  <geom class="visual_iiwa" material="orange_iiwa" mesh="link_6_orange_iiwa" />
                  <geom class="visual_iiwa" mesh="link_6_grey_iiwa" />
                  <geom class="collision_iiwa" size="0.055" pos="0 0 -0.059" />
                  <geom class="collision_iiwa" size="0.065" pos="0 -0.03 0.011" />
                  <geom class="collision_iiwa" size="0.08" />
                  <body name="link7_iiwa_4" pos="0 0.081 0" quat="0 0 1 1">
                    <inertial mass="1.2" pos="0 0 0.02" diaginertia="0.001 0.001 0.001" />
                    <joint name="joint7_iiwa_4" class="joint3_iiwa" />
                    <geom class="visual_iiwa" mesh="link_7_iiwa" />
                    <geom class="collision_iiwa" size="0.06" pos="0 0 0.001" />
                    <site pos="0 0 0.045" name="attachment_site_iiwa_4" />
                  </body>
                </body>
              </body>
            </body>
          </body>
        </body>
      </body>
    </body>
  <body name="base_fr3_5" childclass="fr3" pos="-2 2.0 0.0">
      <body name="fr3_link0_fr3_5">
        <geom mesh="link0_0_fr3" material="black_fr3" class="visual_fr3" />
        <geom mesh="link0_1_fr3" material="white_fr3" class="visual_fr3" />
        <geom mesh="link0_2_fr3" material="white_fr3" class="visual_fr3" />
        <geom mesh="link0_3_fr3" material="white_fr3" class="visual_fr3" />
        <geom mesh="link0_4_fr3" material="white_fr3" class="visual_fr3" />
        <geom mesh="link0_5_fr3" material="red_fr3" class="visual_fr3" />
        <geom mesh="link0_6_fr3" material="black_fr3" class="visual_fr3" />
        <geom name="fr3_link0_collision_fr3_5" mesh="link0_coll_fr3" class="collision_fr3" />
        <body name="fr3_link1_fr3_5" pos="0 0 0.333">
          <inertial pos="4.128e-07 -0.0181251 -0.0386036" quat="0.999901 0.0021545 0.00429041 0.0132325" mass="2.92747" diaginertia="0.0186043 0.0181194 0.00538716" />
          <joint name="fr3_joint1_fr3_5" axis="0 0 1" range="-2.7437 2.7437" actuatorfrcrange="-87 87" />
          <geom name="fr3_link1_collision_fr3_5" class="collision_fr3" mesh="link1_coll_fr3" />
          <geom material="white_fr3" mesh="link1_fr3" class="visual_fr3" />
          <body name="fr3_link2_fr3_5" quat="1 -1 0 0">
            <inertial pos="0.00318289 -0.0743222 0.00881461" quat="0.356855 0.680818 -0.434812 0.469126" mass="2.93554" diaginertia="0.0299291 0.0299291 0.0299291" />
            <joint name="fr3_joint2_fr3_5" axis="0 0 1" range="-1.7837 1.7837" actuatorfrcrange="-87 87" />
            <geom material="white_fr3" mesh="link2_fr3" class="visual_fr3" />
            <geom name="fr3_link2_collision_fr3_5" class="collision_fr3" mesh="link2_coll_fr3" />
            <body name="fr3_link3_fr3_5" pos="0 -0.316 0" quat="1 1 0 0">
              <inertial pos="0.0407016 -0.00482006 -0.0289731" quat="0.950032 -0.148357 0.229935 0.150201" mass="2.2449" diaginertia="0.0140109 0.0140109 0.0140109" />
              <joint name="fr3_joint3_fr3_5" axis="0 0 1" range="-2.9007 2.9007" actuatorfrcrange="-87 87" />
              <geom mesh="link3_0_fr3" material="white_fr3" class="visual_fr3" />
              <geom mesh="link3_1_fr3" material="black_fr3" class="visual_fr3" />
              <geom name="fr3_link3_collision_fr3_5" class="collision_fr3" mesh="link3_coll_fr3" />
              <body name="fr3_link4_fr3_5" pos="0.0825 0 0" quat="1 1 0 0">
                <inertial pos="-0.0459101 0.0630493 -0.00851879" quat="0.23761 0.892458 -0.00078702 0.383484" mass="2.6156" diaginertia="0.0206104 0.0206104 0.0206104" />
                <joint name="fr3_joint4_fr3_5" axis="0 0 1" range="-3.0421 -0.1518" actuatorfrcrange="-87 87" />
                <geom mesh="link4_0_fr3" material="white_fr3" class="visual_fr3" />
                <geom mesh="link4_1_fr3" material="black_fr3" class="visual_fr3" />
                <geom name="fr3_link4_collision_fr3_5" class="collision_fr3" mesh="link4_coll_fr3" />
                <body name="fr3_link5_fr3_5" pos="-0.0825 0.384 0" quat="1 -1 0 0">
                  <inertial pos="-0.00160396 0.0292536 -0.0972966" quat="0.922285 0.098826 0.0982562 -0.360514" mass="2.32712" diaginertia="0.0182879 0.0182879 0.0182879" />
                  <joint name="fr3_joint5_fr3_5" axis="0 0 1" range="-2.8065 2.8065" actuatorfrcrange="-12 12" />
                  <geom mesh="link5_0_fr3" material="white_fr3" class="visual_fr3" />
                  <geom mesh="link5_1_fr3" material="white_fr3" class="visual_fr3" />
                  <geom mesh="link5_2_fr3" material="black_fr3" class="visual_fr3" />
                  <geom name="fr3_link5_collision_fr3_5" class="collision_fr3" mesh="link5_coll_fr3" />
                  <body name="fr3_link6_fr3_5" quat="1 1 0 0">
                    <inertial pos="0.0597131 -0.0410295 -0.0101693" quat="0.593933 0.525442 0.520644 0.316361" mass="1.81704" diaginertia="0.00483538 0.00483538 0.00483538" />
                    <joint name="fr3_joint6_fr3_5" axis="0 0 1" range="0.5445 4.5169" actuatorfrcrange="-12 12" />
                    <geom mesh="link6_0_fr3" material="button_green_fr3" class="visual_fr3" />
                    <geom mesh="link6_1_fr3" material="white_fr3" class="visual_fr3" />
                    <geom mesh="link6_2_fr3" material="white_fr3" class="visual_fr3" />
                    <geom mesh="link6_3_fr3" material="gray_fr3" class="visual_fr3" />
                    <geom mesh="link6_4_fr3" material="button_red_fr3" class="visual_fr3" />
                    <geom mesh="link6_5_fr3" material="white_fr3" class="visual_fr3" />
                    <geom mesh="link6_6_fr3" material="black_fr3" class="visual_fr3" />
                    <geom mesh="link6_7_fr3" material="button_blue_fr3" class="visual_fr3" />
                    <geom name="fr3_link6_collision_fr3_5" class="collision_fr3" mesh="link6_coll_fr3" />
                    <body name="fr3_link7_fr3_5" pos="0.088 0 0" quat="1 1 0 0">
                      <inertial pos="0.00452258 0.00862619 -0.0161633" quat="0.120255 0.394761 -0.799132 0.437139" mass="0.627143" diaginertia="3.076e-07 3.076e-07 3.076e-07" />
                      <joint name="fr3_joint7_fr3_5" axis="0 0 1" range="-3.0159 3.0159" actuatorfrcrange="-12 12" />
                      <geom mesh="link7_0_fr3" material="black_fr3" class="visual_fr3" />
                      <geom mesh="link7_1_fr3" material="white_fr3" class="visual_fr3" />
                      <geom mesh="link7_2_fr3" material="white_fr3" class="visual_fr3" />
                      <geom mesh="link7_3_fr3" material="black_fr3" class="visual_fr3" />
                      <geom name="fr3_link7_collision_fr3_5" class="collision_fr3" mesh="link7_coll_fr3" />
                      <site name="attachment_site_fr3_5" pos="0 0 0.107" />
                    </body>
                  </body>
                </body>
              </body>
            </body>
          </body>
        </body>
      </body>
    </body>
  <body name="link0_panda_6" childclass="panda" pos="2 -2.0 0.0">
      <inertial mass="0.629769" pos="-0.041018 -0.00014 0.049974" fullinertia="0.00315 0.00388 0.004285 8.2904e-7 0.00015 8.2299e-6" />
      <geom mesh="link0_0_panda" material="off_white_panda" class="visual_panda" />
      <geom mesh="link0_1_panda" material="black_panda" class="visual_panda" />
      <geom mesh="link0_2_panda" material="off_white_panda" class="visual_panda" />
      <geom mesh="link0_3_panda" material="black_panda" class="visual_panda" />
      <geom mesh="link0_4_panda" material="off_white_panda" class="visual_panda" />
      <geom mesh="link0_5_panda" material="black_panda" class="visual_panda" />
      <geom mesh="link0_7_panda" material="white_panda" class="visual_panda" />
      <geom mesh="link0_8_panda" material="white_panda" class="visual_panda" />
      <geom mesh="link0_9_panda" material="black_panda" class="visual_panda" />
      <geom mesh="link0_10_panda" material="off_white_panda" class="visual_panda" />
      <geom mesh="link0_11_panda" material="white_panda" class="visual_panda" />
      <geom mesh="link0_c_panda" class="collision_panda" />
      <body name="link1_panda_6" pos="0 0 0.333">
        <inertial mass="4.970684" pos="0.003875 0.002081 -0.04762" fullinertia="0.70337 0.70661 0.0091170 -0.00013900 0.0067720 0.019169" />
        <joint name="joint1_panda_6" />
        <geom material="white_panda" mesh="link1_panda" class="visual_panda" />
        <geom mesh="link1_c_panda" class="collision_panda" />
        <body name="link2_panda_6" quat="1 -1 0 0">
          <inertial mass="0.646926" pos="-0.003141 -0.02872 0.003495" fullinertia="0.0079620 2.8110e-2 2.5995e-2 -3.925e-3 1.0254e-2 7.04e-4" />
          <joint name="joint2_panda_6" range="-1.7628 1.7628" />
          <geom material="white_panda" mesh="link2_panda" class="visual_panda" />
          <geom mesh="link2_c_panda" class="collision_panda" />
          <body name="link3_panda_6" pos="0 -0.316 0" quat="1 1 0 0">
            <joint name="joint3_panda_6" />
            <inertial mass="3.228604" pos="2.7518e-2 3.9252e-2 -6.6502e-2" fullinertia="3.7242e-2 3.6155e-2 1.083e-2 -4.761e-3 -1.1396e-2 -1.2805e-2" />
            <geom mesh="link3_0_panda" material="white_panda" class="visual_panda" />
            <geom mesh="link3_1_panda" material="white_panda" class="visual_panda" />
            <geom mesh="link3_2_panda" material="white_panda" class="visual_panda" />
            <geom mesh="link3_3_panda" material="black_panda" class="visual_panda" />
            <geom mesh="link3_c_panda" class="collision_panda" />
            <body name="link4_panda_6" pos="0.0825 0 0" quat="1 1 0 0">
              <inertial mass="3.587895" pos="-5.317e-2 1.04419e-1 2.7454e-2" fullinertia="2.5853e-2 1.9552e-2 2.8323e-2 7.796e-3 -1.332e-3 8.641e-3" />
              <joint name="joint4_panda_6" range="-3.0718 -0.0698" />
              <geom mesh="link4_0_panda" material="white_panda" class="visual_panda" />
              <geom mesh="link4_1_panda" material="white_panda" class="visual_panda" />
              <geom mesh="link4_2_panda" material="black_panda" class="visual_panda" />
              <geom mesh="link4_3_panda" material="white_panda" class="visual_panda" />
              <geom mesh="link4_c_panda" class="collision_panda" />
              <body name="link5_panda_6" pos="-0.0825 0.384 0" quat="1 -1 0 0">
                <inertial mass="1.225946" pos="-1.1953e-2 4.1065e-2 -3.8437e-2" fullinertia="3.5549e-2 2.9474e-2 8.627e-3 -2.117e-3 -4.037e-3 2.29e-4" />
                <joint name="joint5_panda_6" />
                <geom mesh="link5_0_panda" material="black_panda" class="visual_panda" />
                <geom mesh="link5_1_panda" material="white_panda" class="visual_panda" />
                <geom mesh="link5_2_panda" material="white_panda" class="visual_panda" />
                <geom mesh="link5_c0_panda" class="collision_panda" />
                <geom mesh="link5_c1_panda" class="collision_panda" />
                <geom mesh="link5_c2_panda" class="collision_panda" />
                <body name="link6_panda_6" quat="1 1 0 0">
                  <inertial mass="1.666555" pos="6.0149e-2 -1.4117e-2 -1.0517e-2" fullinertia="1.964e-3 4.354e-3 5.433e-3 1.09e-4 -1.158e-3 3.41e-4" />
                  <joint name="joint6_panda_6" range="-0.0175 3.7525" />
                  <geom mesh="link6_0_panda" material="off_white_panda" class="visual_panda" />
                  <geom mesh="link6_1_panda" material="white_panda" class="visual_panda" />
                  <geom mesh="link6_2_panda" material="black_panda" class="visual_panda" />
                  <geom mesh="link6_3_panda" material="white_panda" class="visual_panda" />
                  <geom mesh="link6_4_panda" material="white_panda" class="visual_panda" />
                  <geom mesh="link6_5_panda" material="white_panda" class="visual_panda" />
                  <geom mesh="link6_6_panda" material="white_panda" class="visual_panda" />
                  <geom mesh="link6_7_panda" material="light_blue_panda" class="visual_panda" />
                  <geom mesh="link6_8_panda" material="light_blue_panda" class="visual_panda" />
                  <geom mesh="link6_9_panda" material="black_panda" class="visual_panda" />
                  <geom mesh="link6_10_panda" material="black_panda" class="visual_panda" />
                  <geom mesh="link6_11_panda" material="white_panda" class="visual_panda" />
                  <geom mesh="link6_12_panda" material="green_panda" class="visual_panda" />
                  <geom mesh="link6_13_panda" material="white_panda" class="visual_panda" />
                  <geom mesh="link6_14_panda" material="black_panda" class="visual_panda" />
                  <geom mesh="link6_15_panda" material="black_panda" class="visual_panda" />
                  <geom mesh="link6_16_panda" material="white_panda" class="visual_panda" />
                  <geom mesh="link6_c_panda" class="collision_panda" />
                  <body name="link7_panda_6" pos="0.088 0 0" quat="1 1 0 0">
                    <inertial mass="7.35522e-01" pos="1.0517e-2 -4.252e-3 6.1597e-2" fullinertia="1.2516e-2 1.0027e-2 4.815e-3 -4.28e-4 -1.196e-3 -7.41e-4" />
                    <joint name="joint7_panda_6" />
                    <geom mesh="link7_0_panda" material="white_panda" class="visual_panda" />
                    <geom mesh="link7_1_panda" material="black_panda" class="visual_panda" />
                    <geom mesh="link7_2_panda" material="black_panda" class="visual_panda" />
                    <geom mesh="link7_3_panda" material="black_panda" class="visual_panda" />
                    <geom mesh="link7_4_panda" material="black_panda" class="visual_panda" />
                    <geom mesh="link7_5_panda" material="black_panda" class="visual_panda" />
                    <geom mesh="link7_6_panda" material="black_panda" class="visual_panda" />
                    <geom mesh="link7_7_panda" material="white_panda" class="visual_panda" />
                    <geom mesh="link7_c_panda" class="collision_panda" />
                    <body name="hand_panda_6" pos="0 0 0.107" quat="0.9238795 0 0 -0.3826834">
                      <inertial mass="0.73" pos="-0.01 0 0.03" diaginertia="0.001 0.0025 0.0017" />
                      <geom mesh="hand_0_panda" material="off_white_panda" class="visual_panda" />
                      <geom mesh="hand_1_panda" material="black_panda" class="visual_panda" />
                      <geom mesh="hand_2_panda" material="black_panda" class="visual_panda" />
                      <geom mesh="hand_3_panda" material="white_panda" class="visual_panda" />
                      <geom mesh="hand_4_panda" material="off_white_panda" class="visual_panda" />
                      <geom mesh="hand_c_panda" class="collision_panda" />
                      <body name="left_finger_panda_6" pos="0 0 0.0584">
                        <inertial mass="0.015" pos="0 0 0" diaginertia="2.375e-6 2.375e-6 7.5e-7" />
                        <joint name="finger_joint1_panda_6" class="finger_panda" />
                        <geom mesh="finger_0_panda" material="off_white_panda" class="visual_panda" />
                        <geom mesh="finger_1_panda" material="black_panda" class="visual_panda" />
                        <geom mesh="finger_0_panda" class="collision_panda" />
                        <geom class="fingertip_pad_collision_1_panda" />
                        <geom class="fingertip_pad_collision_2_panda" />
                        <geom class="fingertip_pad_collision_3_panda" />
                        <geom class="fingertip_pad_collision_4_panda" />
                        <geom class="fingertip_pad_collision_5_panda" />
                      </body>
                      <body name="right_finger_panda_6" pos="0 0 0.0584" quat="0 0 0 1">
                        <inertial mass="0.015" pos="0 0 0" diaginertia="2.375e-6 2.375e-6 7.5e-7" />
                        <joint name="finger_joint2_panda_6" class="finger_panda" />
                        <geom mesh="finger_0_panda" material="off_white_panda" class="visual_panda" />
                        <geom mesh="finger_1_panda" material="black_panda" class="visual_panda" />
                        <geom mesh="finger_0_panda" class="collision_panda" />
                        <geom class="fingertip_pad_collision_1_panda" />
                        <geom class="fingertip_pad_collision_2_panda" />
                        <geom class="fingertip_pad_collision_3_panda" />
                        <geom class="fingertip_pad_collision_4_panda" />
                        <geom class="fingertip_pad_collision_5_panda" />
                      </body>
                    </body>
                  </body>
                </body>
              </body>
            </body>
          </body>
        </body>
      </body>
    </body>
  </worldbody><contact><exclude body1="base_iiwa_3" body2="link1_iiwa_3" />
    <exclude body1="base_iiwa_3" body2="link2_iiwa_3" />
    <exclude body1="base_iiwa_3" body2="link3_iiwa_3" />
    <exclude body1="link1_iiwa_3" body2="link3_iiwa_3" />
    <exclude body1="link3_iiwa_3" body2="link5_iiwa_3" />
    <exclude body1="link4_iiwa_3" body2="link7_iiwa_3" />
    <exclude body1="link5_iiwa_3" body2="link7_iiwa_3" />
  <exclude body1="base_iiwa_4" body2="link1_iiwa_4" />
    <exclude body1="base_iiwa_4" body2="link2_iiwa_4" />
    <exclude body1="base_iiwa_4" body2="link3_iiwa_4" />
    <exclude body1="link1_iiwa_4" body2="link3_iiwa_4" />
    <exclude body1="link3_iiwa_4" body2="link5_iiwa_4" />
    <exclude body1="link4_iiwa_4" body2="link7_iiwa_4" />
    <exclude body1="link5_iiwa_4" body2="link7_iiwa_4" />
  </contact><equality><joint joint1="finger_joint1_panda_6" joint2="finger_joint2_panda_6" solimp="0.95 0.99 0.001" solref="0.005 1" />
  </equality><tendon><fixed name="split_panda_6">
      <joint joint="finger_joint1_panda_6" coef="0.5" />
      <joint joint="finger_joint2_panda_6" coef="0.5" />
    </fixed>
  </tendon><actuator><position name="actuator1_iiwa_3" joint="joint1_iiwa_3" class="joint1_iiwa" />
    <position name="actuator2_iiwa_3" joint="joint2_iiwa_3" class="joint2_iiwa" />
    <position name="actuator3_iiwa_3" joint="joint3_iiwa_3" class="joint1_iiwa" />
    <position name="actuator4_iiwa_3" joint="joint4_iiwa_3" class="joint2_iiwa" />
    <position name="actuator5_iiwa_3" joint="joint5_iiwa_3" class="joint1_iiwa" />
    <position name="actuator6_iiwa_3" joint="joint6_iiwa_3" class="joint2_iiwa" />
    <position name="actuator7_iiwa_3" joint="joint7_iiwa_3" class="joint3_iiwa" />
  <position name="actuator1_iiwa_4" joint="joint1_iiwa_4" class="joint1_iiwa" />
    <position name="actuator2_iiwa_4" joint="joint2_iiwa_4" class="joint2_iiwa" />
    <position name="actuator3_iiwa_4" joint="joint3_iiwa_4" class="joint1_iiwa" />
    <position name="actuator4_iiwa_4" joint="joint4_iiwa_4" class="joint2_iiwa" />
    <position name="actuator5_iiwa_4" joint="joint5_iiwa_4" class="joint1_iiwa" />
    <position name="actuator6_iiwa_4" joint="joint6_iiwa_4" class="joint2_iiwa" />
    <position name="actuator7_iiwa_4" joint="joint7_iiwa_4" class="joint3_iiwa" />
  <position class="fr3" name="fr3_joint1_fr3_5" joint="fr3_joint1_fr3_5" kp="4500" kv="450" />
    <position class="fr3" name="fr3_joint2_fr3_5" joint="fr3_joint2_fr3_5" kp="4500" kv="450" />
    <position class="fr3" name="fr3_joint3_fr3_5" joint="fr3_joint3_fr3_5" kp="3500" kv="350" />
    <position class="fr3" name="fr3_joint4_fr3_5" joint="fr3_joint4_fr3_5" kp="3500" kv="350" />
    <position class="fr3" name="fr3_joint5_fr3_5" joint="fr3_joint5_fr3_5" kp="2000" kv="200" />
    <position class="fr3" name="fr3_joint6_fr3_5" joint="fr3_joint6_fr3_5" kp="2000" kv="200" />
    <position class="fr3" name="fr3_joint7_fr3_5" joint="fr3_joint7_fr3_5" kp="2000" kv="200" />
  <position class="panda" name="actuator1_panda_6" joint="joint1_panda_6" />
    <position class="panda" name="actuator2_panda_6" joint="joint2_panda_6" ctrlrange="-1.7628 1.7628" />
    <position class="panda" name="actuator3_panda_6" joint="joint3_panda_6" />
    <position class="panda" name="actuator4_panda_6" joint="joint4_panda_6" ctrlrange="-3.0718 -0.0698" />
    <position class="panda" name="actuator5_panda_6" joint="joint5_panda_6" forcerange="-12 12" />
    <position class="panda" name="actuator6_panda_6" joint="joint6_panda_6" forcerange="-12 12" ctrlrange="-0.0175 3.7525" />
    <position class="panda" name="actuator7_panda_6" joint="joint7_panda_6" forcerange="-12 12" />
    
    <general class="panda" name="actuator8_panda_6" tendon="split_panda_6" forcerange="-100 100" ctrlrange="0 255" />
  </actuator><keyframe><key name="home" qpos=" 0 0.785398 0 -1.5708 0 0 0 0 0.785398 0 -1.5708 0 0 0 0 0 0 -1.57079 0 1.57079 -0.7853 0 0 0 -1.57079 0 1.57079 -0.7853 0.04 0.04" ctrl=" 0 0.785398 0 -1.5708 0 0 0 0 0.785398 0 -1.5708 0 0 0 0 0 0 -1.57079 0 1.57079 -0.7853 0 0 0 -1.57079 0 1.57079 -0.7853 255" /></keyframe></mujoco>